Workbook

Sheet project
A1: Project_Id | B1: Project | C1: Estimate | D1: Start | E1: Signed_On | F1: Due_Date | G1: Duration | H1: Archived | I1: Archived_Date | J1: Probability | K1: Client_PO | L1: Job_Order | M1: PM | N1: Account | O1: Job_Order_Category | P1: Is_Progress_Percent | Q1: Project_Type | R1: Client | S1: Client_Contact | T1: Program_Charter | U1: Business_Unit | V1: Stage | W1: Suggested_Price | X1: External_Cost | Y1: Internal_Cost | Z1: Travel_Cost | AA1: Expense_Cost | AB1: Progress % | AC1: Budget Consumption % | AD1: Worked hours value | AE1: Invoiced | AF1: Ordered | AG1: Travels | AH1: Expenses | AI1: Internal Cost (Projected) | AJ1: Gross Margin (Last Budget Version) | AK1: Gross Margin % (Last Budget Version) | AL1: Gross Margin (Projected) | AM1: Gross Margin % (Projected) | AN1: Contribution Margin (Last Budget Version) | AO1: Contribution Margin % (Last Budget Version) | AP1: Contribution Margin (Projected) | AQ1: Contribution Margin % (Projected) | AR1: Data chiusura | AS1: Data apertura | AT1: Committente | AU1: Settore | AV1: Finanziato SI/NO | AW1: RIFATTURAZIONE | AX1: Sales Type | AY1: Paesi | AZ1: Intrarea | BA1: Sales 2 | BB1: Numero preventivo
A2: 7 | B2: BOSCAROL SRL_2020 | C2: 11000 | D2: 43831 | G2: 12 | H2: yes | I2: 44596 | J2: 100 | L2: 20B101 | M2: Gaia Seghezzi | N2: Gaia Seghezzi | O2: cliente | Q2: OLD_Temporary Export Management | R2: BOSCAROL SRL | U2: Business Expander | V2: Won | W2: 12000 | Y2: 3840 | AB2: 100 | AC2: 31.56 | AD2: 1212 | AI2: 1212 | AJ2: 11000 | AK2: 100 | AL2: 11000 | AM2: 100 | AN2: 7160 | AO2: 65.090909 | AP2: 9788 | AQ2: 88.981818 | AV2: NO | AX2: SI
A3: 11 | B3: LUCANA SALUMI | C3: 24500 | D3: 44075 | G3: 4 | H3: yes | I3: 44497 | M3: Alessandra Garlini | N3: Alessandra Garlini | O3: cliente | Q3: OLD_Temporary Export Management | R3: Lucana Salumi | U3: Business Expander | V3: Lost | W3: 12250 | X3: 12250 | AJ3: 12250 | AK3: 50 | AL3: 12250 | AM3: 50 | AN3: 12250 | AO3: 50 | AP3: 12250 | AQ3: 50 | AV3: SI | AX3: SI
A4: 12 | B4: Minonzio | C4: 12000 | D4: 43831 | G4: 12 | H4: yes | I4: 44596 | J4: 100 | L4: 20B103 | M4: Alessandra Garlini | N4: Alessandra Garlini | O4: cliente | Q4: OLD_Temporary Export Management | R4: Minonzio Srl | U4: Business Expander | V4: Won | W4: 10400 | Y4: 3648 | AB4: 100 | AC4: 59.38 | AD4: 2964 | AI4: 2964 | AJ4: 12000 | AK4: 100 | AL4: 12000 | AM4: 100 | AN4: 8352 | AO4: 69.6 | AP4: 9036 | AQ4: 75.3 | AV4: NO | AX4: NO
A5: 13 | B5: NTS BE 2020 | C5: 8800 | D5: 43831 | G5: 6 | H5: yes | I5: 44595 | J5: 100 | L5: 19B019 | M5: Francesca Poletti | N5: Giovanna Ricuperati | O5: cliente | Q5: OLD_Temporary Export Management | R5: NTS Spa | U5: Business Expander | V5: Won | W5: 6000 | Y5: 1600 | AB5: 100 | AC5: 41.25 | AD5: 728 | AI5: 728 | AJ5: 8800 | AK5: 100 | AL5: 8800 | AM5: 100 | AN5: 7200 | AO5: 81.818182 | AP5: 8072 | AQ5: 91.727273 | AV5: NO | AX5: SI
A6: 14 | B6: Olio Masturzo_TEM | C6: 8000 | D6: 43831 | G6: 4 | H6: yes | I6: 44596 | J6: 100 | L6: 19B020 | M6: Annalisa Surini | N6: Alessandra Garlini | O6: cliente | Q6: OLD_Temporary Export Management | R6: Oleifici Fratelli Masturzo Snc | U6: Business Expander | V6: Won | W6: 6800 | X6: 800 | Y6: 1920 | AB6: 100 | AC6: 13.75 | AD6: 290 | AI6: 290 | AJ6: 7200 | AK6: 90 | AL6: 8000 | AM6: 100 | AN6: 5280 | AO6: 66 | AP6: 7710 | AQ6: 96.375 | AU6: Food | AV6: SI | AX6: NO | AY6: DACH
A7: 15 | B7: Pirola BE 2020 | C7: 2000 | D7: 43831 | G7: 2 | H7: yes | I7: 44595 | J7: 100 | L7: 19B022 | M7: Francesca Poletti | N7: Alessandra Garlini | O7: cliente | Q7: OLD_Temporary Export Management | R7: Pirola | U7: Business Expander | V7: Won | W7: 2400 | Y7: 640 | AB7: 100 | AJ7: 2000 | AK7: 100 | AL7: 2000 | AM7: 100 | AN7: 1360 | AO7: 68 | AP7: 2000 | AQ7: 100 | AV7: NO | AX7: NO
A8: 16 | B8: SULZER | C8: 28000 | D8: 44013 | G8: 6 | H8: yes | I8: 44497 | M8: Alessandra Garlini | N8: Alessandra Garlini | O8: cliente | Q8: OLD_Temporary Export Management | R8: SULZER SRL | U8: Business Expander | V8: Lost | AJ8: 28000 | AK8: 100 | AL8: 28000 | AM8: 100 | AN8: 28000 | AO8: 100 | AP8: 28000 | AQ8: 100 | AV8: SI | AX8: NO
A9: 17 | B9: Tornilastra | C9: 14000 | D9: 43831 | G9: 12 | H9: yes | I9: 44596 | J9: 100 | L9: 20B106 | M9: Alessandra Garlini | N9: Alessandra Garlini | O9: cliente | Q9: OLD_Temporary Export Management | R9: Tornilastra Srl | U9: Business Expander | V9: Won | W9: 19200 | Y9: 7104 | AB9: 100 | AC9: 2.86 | AD9: 203.5 | AI9: 203.5 | AJ9: 14000 | AK9: 100 | AL9: 14000 | AM9: 100 | AN9: 6896 | AO9: 49.257143 | AP9: 13796.5 | AQ9: 98.546429 | AV9: NO | AX9: SI
A10: 18 | B10: Graziani 2020 | C10: 10000 | D10: 43831 | G10: 12 | H10: yes | I10: 44596 | J10: 100 | L10: 19B046 | M10: Gaia Seghezzi | N10: Claudia Nikolai | O10: cliente | Q10: OLD_Temporary Export Management | R10: Officina Graziani Srl | U10: Business Expander | V10: Won | W10: 7200 | Y10: 2304 | AB10: 100 | AC10: 126.04 | AD10: 2904 | AI10: 2904 | AJ10: 10000 | AK10: 100 | AL10: 10000 | AM10: 100 | AN10: 7696 | AO10: 76.96 | AP10: 7096 | AQ10: 70.96 | AU10: Meccanica | AV10: NO | AX10: SI
A11: 19 | B11: AAB_OMCS PLAST_2020 | C11: 19800 | D11: 43831 | G11: 12 | H11: yes | I11: 44596 | J11: 100 | L11: 20B102 | M11: Alessandra Garlini | N11: Gaia Seghezzi | O11: cliente | Q11: OLD_Temporary Export Management | R11: OMCS PLAST SRL | T11: Associazione Artigiani | U11: Business Expander | V11: Won | W11: 19200 | Y11: 7104 | AB11: 100 | AC11: 134.64 | AD11: 9564.5 | AI11: 9564.5 | AJ11: 19800 | AK11: 100 | AL11: 19800 | AM11: 100 | AN11: 12696 | AO11: 64.121212 | AP11: 10235.5 | AQ11: 51.694444 | AT11: ASSOART | AU11: Gomma e plastica | AV11: NO | AX11: SI | AY11: Europa
A12: 20 | B12: Progtech | C12: 15000 | D12: 43983 | G12: 8 | H12: yes | I12: 44497 | M12: Cristian Pellegrini | N12: Alessandra Garlini | O12: cliente | Q12: OLD_Temporary Export Management | R12: Progtech srl | U12: Business Expander | V12: Lost | AJ12: 15000 | AK12: 100 | AL12: 15000 | AM12: 100 | AN12: 15000 | AO12: 100 | AP12: 15000 | AQ12: 100 | AV12: NO | AX12: NO
A13: 21 | B13: APA MONZA_TEKNOFLUOR SR_2020 | C13: 6300 | D13: 43831 | G13: 7 | H13: yes | I13: 44596 | J13: 100 | L13: 20B109 | M13: Elena Barcella | N13: Alessandra Garlini | O13: cliente | Q13: Sales Expander | R13: Teknofluor Srl | T13: Associazione Artigiani | U13: Business Expander | V13: Won | W13: 5600 | Y13: 1792 | AB13: 100 | AC13: 36.16 | AD13: 660 | AI13: 660 | AJ13: 6300 | AK13: 100 | AL13: 6300 | AM13: 100 | AN13: 4508 | AO13: 71.555556 | AP13: 5640 | AQ13: 89.52381 | AT13: APA MONZA | AV13: NO | AX13: SI
A14: 22 | B14: AAB_FERRARI DIONIGI_19/20 | C14: 4500 | D14: 43831 | G14: 6 | H14: yes | I14: 44595 | J14: 100 | L14: 19B034 | M14: Annalisa Surini | N14: Gaia Seghezzi | O14: cliente | Q14: Sales Expander | R14: FERRARI DIONIGI Srl | T14: Associazione Artigiani | U14: Business Expander | V14: Won | W14: 6000 | Y14: 1920 | AB14: 100 | AC14: 30 | AD14: 589 | AI14: 589 | AJ14: 4500 | AK14: 100 | AL14: 4500 | AM14: 100 | AN14: 2580 | AO14: 57.333333 | AP14: 3911 | AQ14: 86.911111 | AT14: ASSOART | AU14: Meccanica | AV14: NO | AX14: SI | AY14: Italia
A15: 23 | B15: AAB_FORMENTI SRL_20SE | C15: 4050 | D15: 43831 | G15: 5 | H15: yes | I15: 44596 | J15: 100 | L15: 19B035 | M15: Annalisa Surini | N15: Gaia Seghezzi | O15: cliente | Q15: Sales Expander | R15: Formenti Srl | T15: Associazione Artigiani | U15: Business Expander | V15: Won | W15: 4800 | Y15: 1536 | AB15: 100 | AJ15: 4050 | AK15: 100 | AL15: 4050 | AM15: 100 | AN15: 2514 | AO15: 62.074074 | AP15: 4050 | AQ15: 100 | AT15: ASSOART | AU15: Meccanica | AV15: NO | AX15: NO
A16: 24 | B16: AAB_FRATUS SRL | C16: 4725 | D16: 43831 | G16: 4 | H16: yes | I16: 44596 | J16: 100 | L16: 19B037 | M16: Gaia Seghezzi | N16: Gaia Seghezzi | O16: cliente | Q16: Sales Expander | R16: FRATUS Srl | T16: Associazione Artigiani | U16: Business Expander | V16: Won | W16: 4800 | Y16: 1536 | AB16: 100 | AC16: 59.38 | AD16: 912 | AI16: 912 | AJ16: 4725 | AK16: 100 | AL16: 4725 | AM16: 100 | AN16: 3189 | AO16: 67.492063 | AP16: 3813 | AQ16: 80.698413 | AT16: ASSOART | AU16: Gomma e plastica | AV16: NO | AX16: SI
A17: 25 | B17: AAB_OFFICINA MECCANICA RINALDI | C17: 12870 | D17: 43891 | G17: 13 | H17: yes | I17: 44601 | J17: 100 | L17: 20B111 | M17: Valentina Premoli | N17: Gaia Seghezzi | O17: cliente | Q17: Sales Expander | R17: Officina Meccanica Rinaldi Snc | T17: Associazione Artigiani | U17: Business Expander | V17: Won | W17: 10400 | Y17: 3328 | AB17: 100 | AC17: 57.45 | AD17: 1954 | AI17: 1954 | AJ17: 12870 | AK17: 100 | AL17: 12870 | AM17: 100 | AN17: 9542 | AO17: 74.141414 | AP17: 10916 | AQ17: 84.817405 | AT17: ASSOART | AU17: Meccanica | AV17: NO | AX17: NO | AY17: Europa
A18: 26 | B18: AAB_PROJECT PACKAGING_2020 | C18: 12150 | D18: 43831 | G18: 12 | H18: yes | I18: 44596 | J18: 100 | L18: 20B114 | M18: Elena Barcella | N18: Gaia Seghezzi | O18: cliente | Q18: Sales Expander | R18: Project Packaging Srl | T18: Associazione Artigiani | U18: Business Expander | V18: Won | W18: 9600 | Y18: 3072 | AB18: 100 | AC18: 66.15 | AD18: 2221 | AI18: 2221 | AJ18: 12150 | AK18: 100 | AL18: 12150 | AM18: 100 | AN18: 9078 | AO18: 74.716049 | AP18: 9929 | AQ18: 81.720165 | AT18: ASSOART | AU18: Gomma e plastica | AV18: NO | AX18: SI | AY18: Italia
A19: 27 | B19: AAB_RCL DOMINO_2020 | C19: 15086 | D19: 43831 | G19: 12 | H19: yes | I19: 44596 | J19: 100 | L19: 20B110 | M19: Gaia Seghezzi | N19: Gaia Seghezzi | O19: cliente | Q19: Sales Expander | R19: RCL DOMINO Srl | T19: Associazione Artigiani | U19: Business Expander | V19: Won | W19: 14400 | Y19: 4608 | AB19: 100 | AC19: 60.16 | AD19: 2760 | AI19: 2760 | AJ19: 15086 | AK19: 100 | AL19: 15086 | AM19: 100 | AN19: 10478 | AO19: 69.455124 | AP19: 12326 | AQ19: 81.704892 | AT19: ASSOART | AV19: NO | AX19: SI
A20: 28 | B20: AAB_SPINI UOVA_CR | C20: 15000 | D20: 43983 | G20: 12 | H20: yes | I20: 45184 | M20: Valentina Premoli | N20: Gaia Seghezzi | O20: cliente | Q20: Sales Expander | R20: Spini Uova | T20: Associazione Artigiani | U20: Business Expander | V20: Lost | AJ20: 15000 | AK20: 100 | AL20: 15000 | AM20: 100 | AN20: 15000 | AO20: 100 | AP20: 15000 | AQ20: 100 | AT20: ASSOART | AV20: NO | AX20: SI
A21: 29 | B21: AAB_TOP QUALITY | C21: 3240 | D21: 43831 | G21: 3 | H21: yes | I21: 44596 | J21: 100 | L21: 19B043 | M21: Gaia Seghezzi | N21: Gaia Seghezzi | O21: cliente | Q21: Sales Expander | R21: TOP QUALITY Srl | T21: Associazione Artigiani | U21: Business Expander | V21: Won | W21: 6000 | Y21: 1920 | AB21: 100 | AC21: 5.63 | AD21: 108 | AI21: 108 | AJ21: 3240 | AK21: 100 | AL21: 3240 | AM21: 100 | AN21: 1320 | AO21: 40.740741 | AP21: 3132 | AQ21: 96.666667 | AT21: ASSOART | AV21: SI | AX21: SI
A22: 30 | B22: AAB_VALTORTA SRL | C22: 1260 | D22: 43831 | G22: 1 | H22: yes | I22: 44601 | J22: 100 | L22: 19B044 | M22: Valentina Premoli | N22: Gaia Seghezzi | O22: cliente | Q22: Sales Expander | R22: VALTORTA Srl | T22: Associazione Artigiani | U22: Business Expander | V22: Won | W22: 800 | Y22: 256 | AB22: 100 | AJ22: 1260 | AK22: 100 | AL22: 1260 | AM22: 100 | AN22: 1004 | AO22: 79.68254 | AP22: 1260 | AQ22: 100 | AT22: ASSOART | AU22: Meccanica | AV22: NO | AX22: NO
A23: 31 | B23: AAB_LANZENI MARIO_20 | C23: 3240 | D23: 44075 | G23: 3 | H23: yes | I23: 44596 | J23: 100 | L23: 20B132 | M23: Annalisa Surini | N23: Gaia Seghezzi | O23: cliente | Q23: Sales Expander | R23: LANZENI MARIO Srl | T23: Associazione Artigiani | U23: Business Expander | V23: Won | W23: 3600 | Y23: 1152 | AB23: 100 | AC23: 160.42 | AD23: 1560 | AI23: 1560 | AJ23: 3240 | AK23: 100 | AL23: 3240 | AM23: 100 | AN23: 2088 | AO23: 64.444444 | AP23: 1680 | AQ23: 51.851852 | AT23: ASSOART | AU23: Arredamento | AV23: SI | AX23: SI | AY23: Italia
A24: 32 | B24: AAB_SD Laser | C24: 2925 | D24: 43831 | G24: 4 | H24: yes | I24: 44596 | J24: 100 | L24: 19B045 | M24: Elena Barcella | N24: Gaia Seghezzi | O24: cliente | Q24: Sales Expander | R24: SD Laser | T24: Associazione Artigiani | U24: Business Expander | V24: Won | W24: 3200 | Y24: 1024 | AB24: 100 | AJ24: 2925 | AK24: 100 | AL24: 2925 | AM24: 100 | AN24: 1901 | AO24: 64.991453 | AP24: 2925 | AQ24: 100 | AT24: ASSOART | AV24: NO | AX24: SI
A25: 33 | B25: AAB_KRONOS SRL | C25: 12150 | D25: 43862 | G25: 12 | H25: yes | I25: 44601 | J25: 100 | L25: 20B116 | M25: Valentina Premoli | N25: Gaia Seghezzi | O25: cliente | Q25: Sales Expander | R25: Kronos Srl | T25: Associazione Artigiani | U25: Business Expander | V25: Won | W25: 9600 | Y25: 3072 | AB25: 100 | AC25: 62.76 | AD25: 1991 | AI25: 1991 | AJ25: 12150 | AK25: 100 | AL25: 12150 | AM25: 100 | AN25: 9078 | AO25: 74.716049 | AP25: 10159 | AQ25: 83.613169 | AT25: ASSOART | AU25: Altro | AV25: NO | AX25: SI | AY25: Mondo
A26: 34 | B26: AAB_TOP QUALITY_2020/21 | C26: 9900 | D26: 44013 | G26: 8 | H26: yes | I26: 44596 | J26: 100 | L26: 20B146 | M26: Gaia Seghezzi | N26: Gaia Seghezzi | O26: cliente | Q26: Sales Expander | R26: TOP QUALITY Srl | T26: Associazione Artigiani | U26: Business Expander | V26: Won | W26: 9600 | Y26: 3072 | AB26: 100 | AC26: 100.39 | AD26: 2636 | AI26: 2636 | AJ26: 9900 | AK26: 100 | AL26: 9900 | AM26: 100 | AN26: 6828 | AO26: 68.969697 | AP26: 7264 | AQ26: 73.373737 | AT26: ASSOART | AU26: Meccanica | AV26: SI | AX26: SI | AY26: Europa
A27: 35 | B27: AAB_FRATUS SRL_2020/21 | C27: 11756 | D27: 43983 | G27: 9 | H27: yes | I27: 44596 | J27: 100 | L27: 20B127 | M27: Gaia Seghezzi | N27: Gaia Seghezzi | O27: cliente | Q27: Sales Expander | R27: FRATUS Srl | T27: Associazione Artigiani | U27: Business Expander | V27: Won | W27: 11400 | Y27: 3648 | AB27: 100 | AC27: 66.45 | AD27: 2008 | AI27: 2008 | AJ27: 11756 | AK27: 100 | AL27: 11756 | AM27: 100 | AN27: 8108 | AO27: 68.969037 | AP27: 9748 | AQ27: 82.91936 | AT27: ASSOART | AU27: Gomma e plastica | AV27: NO | AX27: SI | AY27: Europa
A28: 37 | B28: AAB_EREDI PIANA_2020 | C28: 12870 | D28: 43862 | G28: 13 | H28: yes | I28: 44601 | J28: 100 | L28: 20B115 | M28: Valentina Premoli | N28: Gaia Seghezzi | O28: cliente | Q28: Sales Expander | R28: Verniciature industriali Eredi Piana S.N.C di Piana Carlo E C. | T28: Associazione Artigiani | U28: Business Expander | V28: Won | W28: 9600 | Y28: 3072 | AB28: 100 | AC28: 53.39 | AD28: 1661 | AI28: 1661 | AJ28: 12870 | AK28: 100 | AL28: 12870 | AM28: 100 | AN28: 9798 | AO28: 76.130536 | AP28: 11209 | AQ28: 87.094017 | AT28: ASSOART | AU28: Meccanica | AV28: NO | AX28: NO | AY28: Italia
A29: 38 | B29: AAB_FERRARI DIONIGI_20/21 | C29: 12150 | D29: 44013 | G29: 12 | H29: yes | I29: 44596 | J29: 100 | L29: 20B144 | M29: Annalisa Surini | N29: Gaia Seghezzi | O29: cliente | Q29: Sales Expander | R29: FERRARI DIONIGI Srl | S29: Francesca Ferrari | T29: Associazione Artigiani | U29: Business Expander | V29: Won | W29: 14700 | Y29: 4704 | AB29: 100 | AC29: 80.48 | AD29: 3406 | AI29: 3406 | AJ29: 12150 | AK29: 100 | AL29: 12150 | AM29: 100 | AN29: 7446 | AO29: 61.283951 | AP29: 8744 | AQ29: 71.967078 | AT29: ASSOART | AU29: Meccanica | AV29: NO | AX29: SI | AY29: Italia
A30: 39 | B30: AAB_FORMENTI SRL_20/21SE | C30: 12150 | D30: 43952 | G30: 12 | H30: yes | I30: 44596 | J30: 100 | L30: 20B128 | M30: Annalisa Surini | N30: Gaia Seghezzi | O30: cliente | Q30: Sales Expander | R30: Formenti Srl | T30: Associazione Artigiani | U30: Business Expander | V30: Won | W30: 14400 | Y30: 4608 | AB30: 100 | AC30: 76.56 | AD30: 3509 | AI30: 3509 | AJ30: 12150 | AK30: 100 | AL30: 12150 | AM30: 100 | AN30: 7542 | AO30: 62.074074 | AP30: 8641 | AQ30: 71.119342 | AT30: ASSOART | AU30: Meccanica | AV30: SI | AX30: SI | AY30: Italia
A31: 40 | B31: AAB_Falegnameria Vitali_2020 | C31: 14850 | D31: 43862 | G31: 12 | H31: yes | I31: 44596 | J31: 100 | L31: 20B117 | M31: Elena Barcella | N31: Gaia Seghezzi | O31: cliente | Q31: Sales Expander | R31: FALEGNAMERIA VITALI FEDERICO DI FAUSTO ED EUGENIO VITALI S.N.C. | T31: Associazione Artigiani | U31: Business Expander | V31: Won | W31: 9600 | Y31: 3072 | AB31: 100 | AC31: 96.09 | AD31: 2994 | AI31: 2994 | AJ31: 14850 | AK31: 100 | AL31: 14850 | AM31: 100 | AN31: 11778 | AO31: 79.313131 | AP31: 11856 | AQ31: 79.838384 | AT31: ASSOART | AU31: Arredamento | AV31: SI | AX31: SI | AY31: Europa
A32: 41 | B32: APA MONZA_Eredi Boffi | C32: 7200 | D32: 43922 | G32: 7 | H32: yes | I32: 44601 | J32: 100 | L32: 20B123 | M32: Valentina Premoli | N32: Gaia Seghezzi | O32: cliente | Q32: Sales Expander | R32: Eredi Di Boffi Mario di Boffi Elio srl | T32: Associazione Artigiani | U32: Business Expander | V32: Won | W32: 7200 | Y32: 2384 | AB32: 100 | AC32: 71.09 | AD32: 1603 | AI32: 1603 | AJ32: 7200 | AK32: 100 | AL32: 7200 | AM32: 100 | AN32: 4816 | AO32: 66.888889 | AP32: 5597 | AQ32: 77.736111 | AT32: APA MONZA | AU32: Meccanica | AV32: NO | AX32: NO
A33: 42 | B33: AAB_OMCF 2020 | C33: 15570 | D33: 43862 | G33: 13 | H33: yes | I33: 44596 | J33: 100 | L33: 20B122 | M33: Elena Barcella | N33: Gaia Seghezzi | O33: cliente | Q33: Sales Expander | R33: OMCF Lavorazioni Meccaniche Srl | T33: Associazione Artigiani | U33: Business Expander | V33: Won | W33: 15200 | Y33: 5064 | AB33: 100 | AC33: 64.2 | AD33: 2796 | AI33: 2796 | AJ33: 15570 | AK33: 100 | AL33: 15570 | AM33: 100 | AN33: 10506 | AO33: 67.475915 | AP33: 12774 | AQ33: 82.042389 | AT33: ASSOART | AU33: Meccanica | AV33: NO | AX33: NO | AY33: Italia
A34: 43 | B34: Blu Elettro | C34: 8000 | D34: 43983 | G34: 6 | H34: yes | I34: 44601 | J34: 100 | M34: Valentina Premoli | N34: Giovanna Ricuperati | O34: cliente | Q34: Sales Expander | R34: Blu Elettro srl | U34: Business Expander | V34: Won | W34: 7200 | Y34: 1920 | AB34: 100 | AC34: 109.9 | AD34: 2045 | AI34: 2045 | AJ34: 8000 | AK34: 100 | AL34: 8000 | AM34: 100 | AN34: 6080 | AO34: 76 | AP34: 5955 | AQ34: 74.4375 | AT34: CNA | AU34: Meccanica | AV34: NO | AX34: NO
A35: 44 | B35: Agla Elettronica BE 2020 | C35: 35000 | D35: 43831 | G35: 15 | H35: yes | I35: 44595 | J35: 100 | L35: 20X106 | M35: Francesca Poletti | N35: Alessandra Garlini | O35: cliente | R35: AGLA Elettronica Srl | U35: Business Expander | V35: Won | W35: 21000 | Y35: 5600 | AB35: 100 | AC35: 56.34 | AD35: 3244.25 | AI35: 3244.25 | AJ35: 35000 | AK35: 100 | AL35: 35000 | AM35: 100 | AN35: 29400 | AO35: 84 | AP35: 31755.75 | AQ35: 90.730714 | AU35: Elettrico/Elettronico | AV35: SI | AX35: SI | AY35: Europa | AZ35: BE-COM
A36: 45 | B36: Trixia Sviluppo Pagode | C36: 3250 | D36: 43891 | G36: 4 | H36: yes | I36: 44621 | J36: 100 | L36: 20X107 | M36: Valentina Bucca | N36: Giovanna Ricuperati | O36: cliente | R36: Trixia Srl - Avalon | S36: d s | U36: Business Expander | V36: Won | W36: 10400 | Y36: 3328 | AB36: 100 | AC36: 65.34 | AD36: 1944 | AI36: 1944 | AJ36: 3250 | AK36: 100 | AL36: 3250 | AM36: 100 | AN36: -78 | AO36: -2.4 | AP36: 1306 | AQ36: 40.184615 | AU36: Edilizia | AV36: NO | AX36: NO
A37: 46 | B37: Calvi marketing 2020 | C37: 90000 | D37: 43831 | G37: 6 | H37: yes | I37: 44621 | J37: 100 | L37: 19B005 | M37: Valentina Bucca | N37: Giovanna Ricuperati | O37: cliente | Q37: Temporary Marketing Management | R37: Calvi Holding s.r.l | U37: Business Expander | V37: Won | W37: 50000 | Y37: 16800 | AB37: 100 | AC37: 10.47 | AD37: 2037 | AI37: 2037 | AJ37: 90000 | AK37: 100 | AL37: 90000 | AM37: 100 | AN37: 73200 | AO37: 81.333333 | AP37: 87963 | AQ37: 97.736667 | AU37: Altro | AV37: NO | AX37: SI
A38: 47 | B38: Affiancamento Calvi Spa | C38: 15000 | D38: 43831 | G38: 12 | H38: yes | I38: 44621 | J38: 100 | L38: 19B006 | M38: Valentina Bucca | N38: Giovanna Ricuperati | O38: cliente | Q38: Temporary Marketing Management | R38: CALVI S.P.A. | U38: Business Expander | V38: Won | W38: 14400 | Y38: 4608 | AB38: 100 | AC38: 7.03 | AD38: 324 | AI38: 324 | AJ38: 15000 | AK38: 100 | AL38: 15000 | AM38: 100 | AN38: 10392 | AO38: 69.28 | AP38: 14676 | AQ38: 97.84 | AU38: Altro | AV38: NO | AX38: SI
A39: 48 | B39: Fimer- ABB | C39: 38000 | D39: 43831 | G39: 4 | H39: yes | I39: 44621 | J39: 100 | L39: 20B108 | M39: Valentina Bucca | N39: Giovanna Ricuperati | O39: cliente | Q39: Assessment | R39: Fimer spa | U39: Business Expander | V39: Won | W39: 32200 | X39: 15000 | Y39: 5824 | AB39: 100 | AF39: 15000 | AJ39: 23000 | AK39: 60.526316 | AL39: 23000 | AM39: 60.526316 | AN39: 17176 | AO39: 45.2 | AP39: 23000 | AQ39: 60.526316 | AU39: Impianti | AV39: NO | AX39: NO
A40: 49 | B40: Assessment Magnetti | C40: 25000 | D40: 44197 | G40: 4 | H40: yes | I40: 44497 | L40: 20B119 | M40: Francesca Gritti | N40: Giovanna Ricuperati | O40: cliente | Q40: Assessment | R40: Magnetti Building spa | U40: Business Expander | V40: Lost | W40: 22600 | Y40: 7032 | AB40: 100 | AC40: 0.89 | AD40: 111 | AI40: 111 | AJ40: 25000 | AK40: 100 | AL40: 25000 | AM40: 100 | AN40: 17968 | AO40: 71.872 | AP40: 24889 | AQ40: 99.556 | AV40: NO | AX40: NO
...

Sheet OLD
A1: Project | B1: Estimate | C1: Check planning | D1: Start | E1: Anno | F1: Due_Date | G1: Duration | H1: Archived | I1: Archived_Date | J1: Probability | K1: Client_PO | L1: Job_Order | M1: PM | N1: Supervisor | O1: Note
A2: 110 Laude_sales expander | B2: 11000 | D2: 46082 | G2: 5 | H2: no | J2: 100 | L2: 26B139 | M2: Lisa Pezzali | N2: Cristian Pellegrini
A3: AAB_ALDEGANI_SE 26 | B3: 12700 | D3: 46113 | G3: 12 | H3: no | J3: 100 | L3: 26B137 | M3: Giulia Pizzati | N3: Cristian Pellegrini
A4: AAB_CORNA IMPIANTI SRL | B4: 10000 | D4: 45992 | G4: 7 | H4: no | J4: 100 | L4: 25B200 | M4: Lisa Pezzali | N4: Annalisa Surini
A5: AAB_CRIMAR_SE 26/27 | B5: 16200 | D5: 46113 | G5: 12 | H5: no | J5: 100 | L5: 26B136 | M5: Lisa Pezzali | N5: Francesca Gritti
A6: AAB_DOMINO_SE 26 | B6: 16200 | D6: 46054 | G6: 12 | H6: no | J6: 100 | L6: 26B116 | M6: Silvia Cortinovis | N6: OK NO | O6: Vede Franci Gritti negli allineamenti con Silvia
A7: AAB_FORMENTI_SE 26_Gestione | B7: 3375 | D7: 46023 | G7: 6 | H7: no | J7: 100 | L7: 26X104 | M7: Silvia Cortinovis | N7: Annalisa Surini
A8: AAB_FRATUS_SE 2026 | B8: 16200 | D8: 45962 | G8: 12 | H8: no | J8: 100 | L8: 25X119 | M8: Ilaria Colleoni | N8: Gaia Seghezzi
A9: AAB_GRAFFIDEA_SE 2026 | B9: 13000 | D9: 46054 | G9: 12 | H9: no | J9: 100 | L9: 26B121 | M9: Lisa Pezzali | N9: Cristian Pellegrini
A10: AAB_KITERM SE 2025-26 | B10: 10500 | D10: 45931 | G10: 12 | H10: no | J10: 100 | L10: 25B193 | M10: Lisa Pezzali | N10: Cristian Pellegrini
A11: AAB_ML ENGRAVING_ SE 26 | B11: 27000 | D11: 46023 | G11: 12 | H11: no | J11: 100 | L11: 26B108 | M11: Silvia Cortinovis | N11: Annalisa Surini
A12: AAB_ML ENGRAVING_EMILIA_SE FINE 25 | B12: 13770 | D12: 45748 | G12: 9 | H12: no | J12: 100 | L12: 25B135 | M12: Silvia Cortinovis | O12: Chiuso? Da archiviare?
A13: AAB_ML ENGRAVING_PIEMONTE FINE 25 | B13: 12240 | D13: 45778 | G13: 8 | H13: no | J13: 100 | L13: 25B136 | M13: Silvia Cortinovis | O13: Chiuso? Da archiviare?
A14: AAB_OFFICINE GAITI_SE 26/27 | B14: 16200 | D14: 46113 | G14: 12 | H14: no | J14: 100 | L14: 26B131 | M14: Lisa Pezzali | N14: Annalisa Surini
A15: AAB_OMCS PLAST_SE 26 | B15: 16200 | D15: 46054 | G15: 12 | H15: no | J15: 100 | L15: 26B119 | M15: Chiara Ballabio | N15: Cristian Pellegrini | O15: PM nuovo post Poletti / Capire chi subentra come supervisor
A16: AAB_OMI SRL_SE | B16: 2800 | D16: 45870 | G16: 2 | H16: no | J16: 100 | L16: 25B179 | M16: Gaia Seghezzi | O16: Chiuso? Da archiviare?
A17: AAB_Plastic technology_SE | B17: 17200 | D17: 45992 | G17: 13 | H17: no | J17: 100 | L17: 25B201 | M17: Lisa Pezzali | N17: Annalisa Surini
A18: AAB_PLASTIMAX_SE 25/26 | B18: 16200 | D18: 45809 | G18: 12 | H18: no | J18: 100 | L18: 25B143 | M18: FRANCESCA BOSIS | N18: Francesca Gritti
A19: AAB_PROJECT PACKAGING_SE 26 | B19: 11700 | D19: 46054 | G19: 12 | H19: no | J19: 100 | L19: 26B115 | M19: Ilaria Colleoni
A20: AAB_VALMATECH_SE 25-26 | B20: 16200 | D20: 45901 | G20: 12 | H20: no | J20: 100 | L20: 25B157 | M20: Giulia Pizzati | N20: Annalisa Surini
A21: AAB_VALMATECH_warm up 25 | B21: 900 | D21: 45839 | G21: 1 | H21: no | J21: 100 | L21: 25B157 | M21: Giulia Pizzati | N21: Annalisa Surini
A22: AAB_VERDELLI_SE 26 | B22: 19350 | D22: 46023 | G22: 12 | H22: no | J22: 100 | L22: 26X102 | M22: Annalisa Surini | N22: Annalisa Surini
A23: AGLA_PRE POST FIERA | B23: 6000 | D23: 46023 | G23: 5 | H23: no | J23: 100 | L23: 26B107 | M23: Francesca Poletti | O23: Chiuso? Da archiviare?
A24: AGRICOOLTUR_Market Test | B24: 24000 | D24: 45839 | G24: 10 | H24: no | J24: 100 | L24: 25B176 | M24: Silvia Cortinovis | O24: Chiuso? Da archiviare?
A25: AMBROSETTI_SE 2026 | B25: 24200 | D25: 46054 | G25: 12 | H25: no | J25: 100 | L25: 26B110 | M25: Giulia Pizzati | N25: Cristian Pellegrini
A26: APA MONZA_TEKNOFLUOR_SE25-26 | B26: 15000 | D26: 45901 | G26: 14 | H26: no | J26: 100 | L26: 25B185 | M26: Ilaria Colleoni | N26: Cristian Pellegrini
A27: ARX_SE 2025-26 | B27: 28000 | D27: 45809 | G27: 12 | H27: no | J27: 100 | L27: 25B133 | M27: Giulia Pizzati | N27: Francesca Gritti
A28: Barbiflex_SE 2026 | B28: 30000 | D28: 46174 | G28: 14 | H28: no | J28: 100 | L28: 26B149 | M28: Chiara Ballabio | N28: Annalisa Surini
A29: BCM srl_sales expander | B29: 30000 | D29: 46113 | G29: 12 | H29: no | J29: 100 | L29: 26B155 | M29: Chiara Ballabio | N29: Cristian Pellegrini
A30: BERTOLONI E BOTTURI _SE 25 | B30: 30000 | D30: 45901 | G30: 12 | H30: no | J30: 100 | L30: 25B177 | M30: Gaia Seghezzi | N30: Gaia Seghezzi | O30: In gestione a Gaia Seghezzi in chiusura
A31: BOSCAROL_M&A | B31: 12000 | D31: 45931 | G31: 4 | H31: no | J31: 100 | L31: 25B168 | M31: Silvia Cortinovis | N31: OK NO | O31: Segue Franci Gritti negli allineamenti con Silvia
A32: BOSCAROL_SE 26 | B32: 12000 | D32: 46023 | G32: 12 | H32: no | J32: 100 | L32: 26X101 | M32: Silvia Cortinovis | N32: OK NO | O32: Segue Franci Gritti negli allineamenti con Silvia
A33: Business Trip Food 2025 extra_Calabria | B33: 880 | D33: 45962 | G33: 4 | H33: no | J33: 100 | L33: 25B121 | M33: Giulia Pizzati | O33: Chiuso? Da archiviare?
A34: CE_DRILLING_SE 26 | B34: 20000 | D34: 46023 | G34: 12 | H34: no | J34: 100 | L34: 26X103 | M34: Chiara Ballabio | N34: Annalisa Surini
A35: CEEVER_SE | B35: 27500 | D35: 45901 | G35: 11 | H35: no | J35: 100 | L35: 25B169 | M35: Chiara Ballabio | N35: Cristian Pellegrini
A36: CERCoop_SE | B36: 36678 | D36: 45931 | G36: 12 | H36: no | J36: 100 | L36: 25B208 | M36: Ilaria Colleoni | N36: Cristian Pellegrini
A37: CFG Serramenti_Affiancamento commerciale | B37: 21000 | D37: 46296 | G37: 7 | H37: no | J37: 100 | L37: 26B138 | M37: Annalisa Surini | N37: Annalisa Surini
A38: CFG SERRAMENTI_Assessment | B38: 16200 | D38: 46143 | G38: 3 | H38: no | J38: 100 | L38: 26B138 | M38: Francesca Poletti
A39: CFG Serramenti_Formazione | B39: 5400 | D39: 46235 | G39: 2 | H39: no | J39: 100 | L39: 26B138 | M39: Annalisa Surini | N39: Annalisa Surini
A40: CHEZ MOI ITALIA_ SE 27 | B40: 12000 | D40: 46327 | G40: 5 | H40: no | J40: 90 | M40: Gaia Seghezzi | O40: Parte a Novembre
...

Sheet Pivot
A1: Probability | B1: (più elementi)
A2: Business_Unit | B2: (più elementi)
A3: Archived | B3: no
A5: Project | B5: PM | C5: =+VLOOKUP(A5,OLD!A:N,14,0) -> Supervisor
A6: 110 Laude_sales expander | B6: Lisa Pezzali | C6: =+VLOOKUP(A6,OLD!A:N,14,0) -> Cristian Pellegrini
A7: AAB_ALDEGANI_SE 26-27 | B7: Giulia Pizzati | C7: Cristian Pellegrini
A8: AAB_CORNA IMPIANTI SE SETT '26 | B8: Lisa Pezzali | C8: Annalisa Surini
A9: AAB_CRIMAR_SE 26/27 | B9: Lisa Pezzali | C9: =+VLOOKUP(A9,OLD!A:N,14,0) -> Francesca Gritti
A10: AAB_DOMINO_SE 26 | B10: Silvia Cortinovis | C10: =+VLOOKUP(A10,OLD!A:N,14,0) -> OK NO
A11: AAB_FORMENTI_SE 26_2 | B11: Silvia Cortinovis | C11: Annalisa Surini
A12: AAB_FRATUS_DEM 26 | B12: Ilaria Colleoni | C12: Gaia Seghezzi
A13: AAB_FRATUS_SE 2026 | B13: Ilaria Colleoni | C13: =+VLOOKUP(A13,OLD!A:N,14,0) -> Gaia Seghezzi
A14: AAB_GRAFFIDEA_SE 2026 | B14: Lisa Pezzali | C14: =+VLOOKUP(A14,OLD!A:N,14,0) -> Cristian Pellegrini
A15: AAB_KITERM SE 2025-26 | B15: Lisa Pezzali | C15: =+VLOOKUP(A15,OLD!A:N,14,0) -> Cristian Pellegrini
A16: AAB_KITERM SE 26/27 | B16: Lisa Pezzali | C16: Cristian Pellegrini
A17: AAB_ML ENGRAVING_ SE 26 | B17: Silvia Cortinovis | C17: =+VLOOKUP(A17,OLD!A:N,14,0) -> Annalisa Surini
A18: AAB_OFFICINE GAITI_SE 26/27 | B18: Lisa Pezzali | C18: =+VLOOKUP(A18,OLD!A:N,14,0) -> Annalisa Surini
A19: AAB_OMCS PLAST_SE 26 | B19: Chiara Ballabio | C19: =+VLOOKUP(A19,OLD!A:N,14,0) -> Cristian Pellegrini
A20: AAB_Plastic technology_SE | B20: Lisa Pezzali | C20: =+VLOOKUP(A20,OLD!A:N,14,0) -> Annalisa Surini
A21: AAB_VALMATECH_SE 26-27 | B21: Giulia Pizzati | C21: Annalisa Surini
A22: AAB_VERDELLI_SE 26 | B22: Annalisa Surini | C22: =+VLOOKUP(A22,OLD!A:N,14,0) -> Annalisa Surini
A23: AMBROSETTI_SE 26-27 | B23: Giulia Pizzati | C23: Cristian Pellegrini
A24: ANIMA DESK EUROPA | B24: Valentina Bucca
A25: APA MONZA_TEKNOFLUOR_SE25-26 | B25: Ilaria Colleoni | C25: =+VLOOKUP(A25,OLD!A:N,14,0) -> Cristian Pellegrini
A26: Barbiflex_SE 2026 | B26: Chiara Ballabio | C26: =+VLOOKUP(A26,OLD!A:N,14,0) -> Annalisa Surini
A27: BCM srl_sales expander | B27: Chiara Ballabio | C27: =+VLOOKUP(A27,OLD!A:N,14,0) -> Cristian Pellegrini
A28: BERTOLONI E BOTTURI _SE 25 | B28: FRANCESCA BOSIS | C28: =+VLOOKUP(A28,OLD!A:N,14,0) -> Gaia Seghezzi
A29: BOSCAROL_M&A | B29: Silvia Cortinovis | C29: =+VLOOKUP(A29,OLD!A:N,14,0) -> OK NO
A30: BOSCAROL_SE 26 | B30: Silvia Cortinovis | C30: =+VLOOKUP(A30,OLD!A:N,14,0) -> OK NO
A31: CE_DRILLING_SE 26 | B31: Chiara Ballabio | C31: =+VLOOKUP(A31,OLD!A:N,14,0) -> Annalisa Surini
A32: CEEVER_SE | B32: Chiara Ballabio | C32: =+VLOOKUP(A32,OLD!A:N,14,0) -> Cristian Pellegrini
A33: CERCoop_SE | B33: Ilaria Colleoni | C33: =+VLOOKUP(A33,OLD!A:N,14,0) -> Cristian Pellegrini
A34: CFG Serramenti_Affiancamento commerciale | B34: Annalisa Surini | C34: =+VLOOKUP(A34,OLD!A:N,14,0) -> Annalisa Surini
A35: CFG Serramenti_Formazione | B35: Annalisa Surini | C35: =+VLOOKUP(A35,OLD!A:N,14,0) -> Annalisa Surini
A36: CHEZ MOI ITALIA_ SE 27 | B36: Gaia Seghezzi
A37: CICLOTTE 2026 | B37: Bonfanti Luca
A38: CMA TEC_Fiera BIMU | B38: Chiara Ballabio | C38: Cristian Pellegrini
A39: CMA TEC_SE 2026 | B39: Chiara Ballabio | C39: =+VLOOKUP(A39,OLD!A:N,14,0) -> Cristian Pellegrini
A40: COLORICHIARI_SE 26 | B40: Giulia Pizzati | C40: Cristian Pellegrini
A41: COMINTEC_SE 26 | B41: Annalisa Surini | C41: =+VLOOKUP(A41,OLD!A:N,14,0) -> Annalisa Surini
...

Sheet Supervisor
A1: Project | B1: PM | C1: Supervisor | D1: Note
A2: 110 Laude_sales expander | B2: Lisa Pezzali | C2: Cristian Pellegrini
A3: AAB_ALDEGANI_SE 26-27 | B3: Giulia Pizzati | C3: Cristian Pellegrini
A4: AAB_CORNA IMPIANTI SE SETT '26 | B4: Lisa Pezzali | C4: Annalisa Surini
A5: AAB_CRIMAR_SE 26/27 | B5: Lisa Pezzali | C5: Francesca Gritti
A6: AAB_DOMINO_SE 26 | B6: Silvia Cortinovis | C6: Francesca Gritti | D6: Vede Franci Gritti negli allineamenti con Silvia
A7: AAB_FORMENTI_SE 26_2 | B7: Silvia Cortinovis | C7: Annalisa Surini
A8: AAB_FRATUS_DEM 26 | B8: Ilaria Colleoni | C8: Gaia Seghezzi
A9: AAB_FRATUS_SE 2026 | B9: Ilaria Colleoni | C9: Gaia Seghezzi
A10: AAB_GRAFFIDEA_SE 2026 | B10: Lisa Pezzali | C10: Cristian Pellegrini
A11: AAB_KITERM SE 2025-26 | B11: Lisa Pezzali | C11: Cristian Pellegrini
A12: AAB_KITERM SE 26/27 | B12: Lisa Pezzali | C12: Cristian Pellegrini
A13: AAB_ML ENGRAVING_ SE 26 | B13: Silvia Cortinovis | C13: Annalisa Surini
A14: AAB_OFFICINE GAITI_SE 26/27 | B14: Lisa Pezzali | C14: Annalisa Surini
A15: AAB_OMCS PLAST_SE 26 | B15: Chiara Ballabio | C15: Cristian Pellegrini
A16: AAB_Plastic technology_SE | B16: Lisa Pezzali | C16: Annalisa Surini
A17: AAB_VALMATECH_SE 26-27 | B17: Giulia Pizzati | C17: Annalisa Surini
A18: AAB_VERDELLI_SE 26 | B18: Annalisa Surini | C18: Annalisa Surini
... A23: BCM srl_sales expander | B23: Chiara Ballabio | C23: Cristian Pellegrini
A24: BERTOLONI E BOTTURI _SE 25 | B24: FRANCESCA BOSIS | C24: Gaia Seghezzi | D24: In gestione a Gaia Seghezzi in chiusura
A25: BOSCAROL_M&A | B25: Silvia Cortinovis | C25: Francesca Gritti | D25: Segue Franci Gritti negli allineamenti con Silvia
A26: BOSCAROL_SE 26 | B26: Silvia Cortinovis | C26: Francesca Gritti | D26: Segue Franci Gritti negli allineamenti con Silvia
A27: CE_DRILLING_SE 26 | B27: Chiara Ballabio | C27: Annalisa Surini
A28: CEEVER_SE | B28: Chiara Ballabio | C28: Cristian Pellegrini
A29: CERCoop_SE | B29: Ilaria Colleoni | C29: Cristian Pellegrini
A30: CFG Serramenti_Affiancamento commerciale | B30: Annalisa Surini | C30: Annalisa Surini
A31: CFG Serramenti_Formazione | B31: Annalisa Surini | C31: Annalisa Surini
A32: CHEZ MOI ITALIA_ SE 27 | B32: Gaia Seghezzi | D32: Parte a Novembre
A33: CMA TEC_Fiera BIMU | B33: Chiara Ballabio | C33: Cristian Pellegrini
A34: CMA TEC_SE 2026 | B34: Chiara Ballabio | C34: Cristian Pellegrini
A35: COLORICHIARI_SE 26 | B35: Giulia Pizzati | C35: Cristian Pellegrini
A36: COMINTEC_SE 26 | B36: Annalisa Surini | C36: Annalisa Surini
A37: ComoNExT_sales expander | B37: Silvia Cortinovis | C37: Francesca Gritti | D37: Presidio di Franci Gelmini + segue Franci Gritti negli allineamenti con Silvia
A38: COMPUTES GROUP_SE 2026-2027 | B38: Chiara Ballabio | C38: Cristian Pellegrini
A39: CONF BARI_INCOMING MODA 2026 | B39: Ilaria Colleoni | C39: Annalisa Surini
A40: Confcooperative Bergamo_Promozione filiera manifatturiera | B40: Cristian Pellegrini | C40: Cristian Pellegrini
A41: E.D. Elettronica dedicata_affiancamento marketing 2026 | B41: Valentina Bucca | C41: Valentina Bucca
A42: E.D. Elettronica Dedicata_SE | B42: Chiara Ballabio | C42: Valentina Bucca? | D42: Possiamo liberare Cristina Pellegrini?
A43: ELETTROARMATURE_2026 | B43: Giulia Pizzati | C43: Francesca Gritti | D43: Solo gestione + segue Franci Gritti negli allineamenti con Giulia
A44: ENNISWORK_SE 26 | B44: Ilaria Colleoni | C44: Cristian Pellegrini
...
